Workbook
Name Print_Area: REPUESTOS!$A$1:$O$234
Name Print_Area: 'REPUESTOS (2)'!$A$1:$P$236

Sheet REPUESTOS (2)
K2: U$S | L2: 1470 | M2: Fracción para BMC | N2: Combo | O2: 0.7
N3: Turbina | O3: 0.6
F4: SEPID S.A. | N4: Placa | O4: 0.5
F5: LISTA DE COSTO VIGENTE | K5: PRECIO LISTA | L5: PARTICULAR | M5: BONIFICADOS | N5: RESP/LANC | O5: PUBLICO
A6: Última Fecha | B6: Código P. | C6: Proveedor | D6: Costo NETO | E6: Costo PESOS | F6: REPUESTOS | G6: Nombre encontrado en códigos | H6: Marca | I6: Detalle | J6: MUL | K6: VENTA | L6: VENTA | M6: VENTA | N6: VENTA | O6: VENTA
F7: BMC
F8: CPAP G1
A9: 42682 | B9: TU001 | C9: BMC | D9: 50 | E9: =D9*$L$2 -> 73500 | F9: TURBINA CPAP RESmart | G9: =VLOOKUP(B9,CÓDIGOS!$A$1:$B$1000,2) -> Turbina CPAP GI | J9: 1 | K9: =D9*$L$2*J9 -> 73500 | L9: =K9*1.1 -> 80850 | M9: =K9*5/6 -> 61250
A10: 42682 | B10: PL002 | C10: BMC | D10: 50 | E10: =D10*$L$2 -> 73500 | F10: PLACA PRINCIPAL CPAP RESmart | G10: =VLOOKUP(B10,CÓDIGOS!$A$1:$B$1000,2) -> Placa principal CPAP G1 | J10: 1 | K10: =D10*$L$2*J10 -> 73500 | L10: =K10*1.1 -> 80850 | M10: =K10*5/6 -> 61250
D11: =K11/1.5 -> 333.33333 | E11: =D11*$L$2 -> 490000 | F11: BPAP G1 | G11: =VLOOKUP(B11,CÓDIGOS!$A$1:$B$1000,2) -> #N/A | K11: 500 | L11: =K11*1.1 -> 550 | M11: =K11*5/6 -> 416.66667
A12: 42682 | C12: BMC | D12: =D11*O3 -> 200 | E12: =D12*$L$2 -> 294000 | F12: TURBINA BPAP 25 | G12: =VLOOKUP(B12,CÓDIGOS!$A$1:$B$1000,2) -> #N/A | J12: 1.5 | K12: =D12*$L$2*J12 -> 441000 | L12: =K12*1.1 -> 485100 | M12: =K12*5/6 -> 367500
A13: 42682 | C13: BMC | D13: =D11*O3 -> 200 | E13: =D13*$L$2 -> 294000 | F13: TURBINA BPAP 30T | G13: =VLOOKUP(B13,CÓDIGOS!$A$1:$B$1000,2) -> #N/A | J13: 1.5 | K13: =D13*$L$2*J13 -> 441000 | L13: =K13*1.1 -> 485100 | M13: =K13*5/6 -> 367500
A14: 42682 | C14: BMC | D14: =D11*O3 -> 200 | E14: =D14*$L$2 -> 294000 | F14: TURBINA BPAP 25A & 25T | G14: =VLOOKUP(B14,CÓDIGOS!$A$1:$B$1000,2) -> #N/A | J14: 1.5 | K14: =D14*$L$2*J14 -> 441000 | L14: =K14*1.1 -> 485100 | M14: =K14*5/6 -> 367500
A15: 42682 | C15: BMC | D15: =D11*O4 -> 166.66667 | E15: =D15*$L$2 -> 245000 | F15: PLACA PRINCIPAL BPAP 25 | G15: =VLOOKUP(B15,CÓDIGOS!$A$1:$B$1000,2) -> #N/A | J15: 1.5 | K15: =D15*$L$2*J15 -> 367500 | L15: =K15*1.1 -> 404250 | M15: =K15*5/6 -> 306250
A16: 42682 | C16: BMC | D16: =D11*O4 -> 166.66667 | E16: =D16*$L$2 -> 245000 | F16: PLACA PRINCIPAL BPAP 25A & 25T | G16: =VLOOKUP(B16,CÓDIGOS!$A$1:$B$1000,2) -> #N/A | J16: 1.5 | K16: =D16*$L$2*J16 -> 367500 | L16: =K16*1.1 -> 404250 | M16: =K16*5/6 -> 306250
A17: 42682 | C17: BMC | D17: =D11*O4 -> 166.66667 | E17: =D17*$L$2 -> 245000 | F17: PLACA PRINCIPAL BPAP 30T | G17: =VLOOKUP(B17,CÓDIGOS!$A$1:$B$1000,2) -> #N/A | J17: 1.5 | K17: =D17*$L$2*J17 -> 367500 | L17: =K17*1.1 -> 404250 | M17: =K17*5/6 -> 306250
D18: =D11*O2 -> 233.33333 | E18: =D18*$L$2 -> 343000 | F18: COMBO | G18: =VLOOKUP(B18,CÓDIGOS!$A$1:$B$1000,2) -> #N/A | J18: 1.5 | K18: =D18*$L$2*J18 -> 514500 | L18: =K18*1.1 -> 565950 | M18: =K18*5/6 -> 428750
D19: =K19/1.5 -> 100 | E19: =D19*$L$2 -> 147000 | F19: AUTO CPAP G1 | G19: =VLOOKUP(B19,CÓDIGOS!$A$1:$B$1000,2) -> #N/A | J19: 1.5 | K19: 150 | L19: =K19*1.1 -> 165 | M19: =K19*5/6 -> 125
A20: 42682 | C20: BMC | D20: 50 | E20: =D20*$L$2 -> 73500 | F20: TURBINA AUTOCPAP RESmartAUTO | G20: =VLOOKUP(B20,CÓDIGOS!$A$1:$B$1000,2) -> #N/A | J20: 1.5 | K20: =D20*$L$2*J20 -> 110250 | L20: =K20*1.1 -> 121275 | M20: =K20*5/6 -> 91875
A21: 42682 | C21: BMC | D21: 80 | E21: =D21*$L$2 -> 117600 | F21: PLACA PRINCIPAL AUTO CPAP RESmart AUTO | G21: =VLOOKUP(B21,CÓDIGOS!$A$1:$B$1000,2) -> #N/A | J21: 1.5 | K21: =D21*$L$2*J21 -> 176400 | L21: =K21*1.1 -> 194040 | M21: =K21*5/6 -> 147000
E22: =D22*$L$2 -> 0 | F22: GII | G22: =VLOOKUP(B22,CÓDIGOS!$A$1:$B$1000,2) -> #N/A | J22: 1.5 | L22: =K22*1.1 -> 0 | M22: =K22*5/6 -> 0
D23: =K23/1.5 -> 166.66667 | E23: =D23*$L$2 -> 245000 | F23: E-20C-H-O | G23: =VLOOKUP(B23,CÓDIGOS!$A$1:$B$1000,2) -> #N/A | J23: 1.5 | K23: 250 | L23: =K23*1.1 -> 275 | M23: =K23*5/6 -> 208.33333
A24: 44992 | C24: BMC | D24: =D23*O3 -> 100 | E24: =D24*$L$2 -> 147000 | F24: TURBINA nP2-C2 | G24: =VLOOKUP(B24,CÓDIGOS!$A$1:$B$1000,2) -> #N/A | J24: 1.5 | K24: =D24*$L$2*J24 -> 220500 | L24: =K24*1.1 -> 242550 | M24: =K24*5/6 -> 183750
A25: 44992 | C25: BMC | D25: =D23*O4 -> 83.333333 | E25: =D25*$L$2 -> 122500 | F25: PLACA DE CONTROL E-20C-H-O | G25: =VLOOKUP(B25,CÓDIGOS!$A$1:$B$1000,2) -> #N/A | J25: 1.5 | K25: =D25*$L$2*J25 -> 183750 | L25: =K25*1.1 -> 202125 | M25: =K25*5/6 -> 153125
D26: =D23*$O$2 -> 116.66667 | E26: =D26*$L$2 -> 171500 | F26: COMBO | G26: =VLOOKUP(B26,CÓDIGOS!$A$1:$B$1000,2) -> #N/A | J26: 1.5 | K26: =D26*$L$2*J26 -> 257250 | L26: =K26*1.1 -> 282975 | M26: =K26*5/6 -> 214375
D27: =K27/1.5 -> 200 | E27: =D27*$L$2 -> 294000 | F27: E-20A-H-O | G27: =VLOOKUP(B27,CÓDIGOS!$A$1:$B$1000,2) -> #N/A | J27: 1.5 | K27: 300 | L27: =K27*1.1 -> 330 | M27: =K27*5/6 -> 250
A28: 44992 | C28: BMC | D28: =D27*O3 -> 120 | E28: =D28*$L$2 -> 176400 | F28: TURBINA nP2-M3+ | G28: =VLOOKUP(B28,CÓDIGOS!$A$1:$B$1000,2) -> #N/A | J28: 1.5 | K28: =D28*$L$2*J28 -> 264600 | L28: =K28*1.1 -> 291060 | M28: =K28*5/6 -> 220500
A29: 44992 | B29: 1502001 | C29: BMC | D29: =D27*O4 -> 100 | E29: =D29*$L$2 -> 147000 | F29: PLACA DE CONTROL E-20A-H-O | G29: =VLOOKUP(B29,CÓDIGOS!$A$1:$B$1000,2) -> Placa de circuito impresoÂ ensamblada APAP 20A-H-O | J29: 1.5 | K29: =D29*$L$2*J29 -> 220500 | L29: =K29*1.1 -> 242550 | M29: =K29*5/6 -> 183750
A30: 44992 | C30: BMC | D30: =D27*O2 -> 140 | E30: =D30*$L$2 -> 205800 | F30: COMBO | G30: =VLOOKUP(B30,CÓDIGOS!$A$1:$B$1000,2) -> #N/A | J30: 1.5 | K30: =D30*$L$2*J30 -> 308700 | L30: =K30*1.1 -> 339570 | M30: =K30*5/6 -> 257250
D31: =K31/1.5 -> 566.66667 | E31: =D31*$L$2 -> 833000 | F31: BPAP T-25T | G31: =VLOOKUP(B31,CÓDIGOS!$A$1:$B$1000,2) -> #N/A | J31: 1.5 | K31: 850 | L31: =K31*1.1 -> 935 | M31: =K31*5/6 -> 708.33333
A32: 44992 | C32: BMC | D32: =D31*O3 -> 340 | E32: =D32*$L$2 -> 499800 | F32: TURBINA G2 T | G32: =VLOOKUP(B32,CÓDIGOS!$A$1:$B$1000,2) -> #N/A | J32: 1.5 | K32: =D32*$L$2*J32 -> 749700 | L32: =K32*1.1 -> 824670 | M32: =K32*5/6 -> 624750
A33: 44992 | C33: BMC | D33: =D31*O4 -> 283.33333 | E33: =D33*$L$2 -> 416500 | F33: PLACA DE CONTROL T-25T | G33: =VLOOKUP(B33,CÓDIGOS!$A$1:$B$1000,2) -> #N/A | J33: 1.5 | K33: =D33*$L$2*J33 -> 624750 | L33: =K33*1.1 -> 687225 | M33: =K33*5/6 -> 520625
A34: 44992 | C34: BMC | D34: =D31*O2 -> 396.66667 | E34: =D34*$L$2 -> 583100 | F34: COMBO | G34: =VLOOKUP(B34,CÓDIGOS!$A$1:$B$1000,2) -> #N/A | J34: 1.5 | K34: =D34*$L$2*J34 -> 874650 | L34: =K34*1.1 -> 962115 | M34: =K34*5/6 -> 728875
D35: =K35/1.5 -> 633.33333 | E35: =D35*$L$2 -> 931000 | F35: BPAP Y-25T | G35: =VLOOKUP(B35,CÓDIGOS!$A$1:$B$1000,2) -> #N/A | J35: 1.5 | K35: 950 | L35: =K35*1.1 -> 1045 | M35: =K35*5/6 -> 791.66667
D36: =D35*O3 -> 380 | E36: =D36*$L$2 -> 558600 | F36: TURBINA G2 T | G36: =VLOOKUP(B36,CÓDIGOS!$A$1:$B$1000,2) -> #N/A | J36: 1.5 | K36: =D32*$L$2*J32 -> 749700 | L36: =K36*1.1 -> 824670 | M36: =K36*5/6 -> 624750
D37: =D35*O4 -> 316.66667 | E37: =D37*$L$2 -> 465500 | F37: PLACA CONTROL Y-25T | G37: =VLOOKUP(B37,CÓDIGOS!$A$1:$B$1000,2) -> #N/A | J37: 1.5 | K37: =D33*$L$2*J33 -> 624750 | L37: =K37*1.1 -> 687225 | M37: =K37*5/6 -> 520625
D38: =D35*O2 -> 443.33333 | E38: =D38*$L$2 -> 651700 | F38: COMBO | G38: =VLOOKUP(B38,CÓDIGOS!$A$1:$B$1000,2) -> #N/A | J38: 1.5 | K38: =D34*$L$2*J34 -> 874650 | L38: =K38*1.1 -> 962115 | M38: =K38*5/6 -> 728875
A39: 44992 | C39: BMC | E39: =D39*$L$2 -> 0 | F39: PLACA DE CONTROL Y-30T | G39: =VLOOKUP(B39,CÓDIGOS!$A$1:$B$1000,2) -> #N/A | J39: 1.5 | L39: =K39*1.1 -> 0 | M39: =K39*5/6 -> 0
A40: 44992 | C40: BMC | E40: =D40*$L$2 -> 0 | F40: PLACA DE CONTROL Y-30A | G40: =VLOOKUP(B40,CÓDIGOS!$A$1:$B$1000,2) -> #N/A | J40: 1.5 | K40: =D40*$L$2*J40 -> 0 | L40: =K40*1.1 -> 0 | M40: =K40*5/6 -> 0
E41: =D41*$L$2 -> 0 | F41: G2S | G41: =VLOOKUP(B41,CÓDIGOS!$A$1:$B$1000,2) -> #N/A | J41: 1.5 | L41: =K41*1.1 -> 0 | M41: =K41*5/6 -> 0
...

Sheet REPUESTOS
J2: U$S | K2: 1470 | L2: Fracción para BMC | M2: Combo | N2: 0.7
M3: Turbina | N3: 0.6
F4: SEPID S.A. | M4: Placa | N4: 0.5
F5: LISTA DE COSTO VIGENTE | J5: PRECIO LISTA | K5: PARTICULAR | L5: BONIFICADOS | M5: RESP/LANC | N5: PUBLICO
A6: Última Fecha | B6: Código P. | C6: Proveedor | D6: Costo NETO | E6: Costo PESOS | F6: REPUESTOS | G6: Marca | H6: Detalle | I6: MUL | J6: VENTA | K6: VENTA | L6: VENTA | M6: VENTA | N6: VENTA
F7: BMC
F8: CPAP G1
A9: 42682 | B9: TU001 | C9: BMC | D9: 50 | E9: =D9*$K$2 -> 73500 | F9: TURBINA CPAP RESmart | I9: 1 | J9: =D9*$K$2*I9 -> 73500 | K9: =J9*1.1 -> 80850 | L9: =J9*5/6 -> 61250
A10: 42682 | B10: PL001 | C10: BMC | D10: 50 | E10: =D10*$K$2 -> 73500 | F10: PLACA PRINCIPAL CPAP RESmart | I10: 1 | J10: =D10*$K$2*I10 -> 73500 | K10: =J10*1.1 -> 80850 | L10: =J10*5/6 -> 61250
D11: =J11/1.5 -> 333.33333 | E11: =D11*$K$2 -> 490000 | F11: BPAP G1 | J11: 500 | K11: =J11*1.1 -> 550 | L11: =J11*5/6 -> 416.66667
A12: 42682 | B12: 1501004 | C12: BMC | D12: =D11*N3 -> 200 | E12: =D12*$K$2 -> 294000 | F12: TURBINA BPAP 25 | I12: 1.5 | J12: =D12*$K$2*I12 -> 441000 | K12: =J12*1.1 -> 485100 | L12: =J12*5/6 -> 367500
A13: 42682 | B13: 1501003 | C13: BMC | D13: =D11*N3 -> 200 | E13: =D13*$K$2 -> 294000 | F13: TURBINA BPAP 30T | I13: 1.5 | J13: =D13*$K$2*I13 -> 441000 | K13: =J13*1.1 -> 485100 | L13: =J13*5/6 -> 367500
A14: 42682 | B14: 1501001 | C14: BMC | D14: =D11*N3 -> 200 | E14: =D14*$K$2 -> 294000 | F14: TURBINA BPAP 25A & 25T | I14: 1.5 | J14: =D14*$K$2*I14 -> 441000 | K14: =J14*1.1 -> 485100 | L14: =J14*5/6 -> 367500
A15: 42682 | B15: PL002 | C15: BMC | D15: =D11*N4 -> 166.66667 | E15: =D15*$K$2 -> 245000 | F15: PLACA PRINCIPAL BPAP 25 | I15: 1.5 | J15: =D15*$K$2*I15 -> 367500 | K15: =J15*1.1 -> 404250 | L15: =J15*5/6 -> 306250
A16: 42682 | B16: SC-101 | C16: BMC | D16: =D11*N4 -> 166.66667 | E16: =D16*$K$2 -> 245000 | F16: PLACA PRINCIPAL BPAP 25A & 25T | I16: 1.5 | J16: =D16*$K$2*I16 -> 367500 | K16: =J16*1.1 -> 404250 | L16: =J16*5/6 -> 306250
A17: 42682 | B17: SC-104 | C17: BMC | D17: =D11*N4 -> 166.66667 | E17: =D17*$K$2 -> 245000 | F17: PLACA PRINCIPAL BPAP 30T | I17: 1.5 | J17: =D17*$K$2*I17 -> 367500 | K17: =J17*1.1 -> 404250 | L17: =J17*5/6 -> 306250
D18: =D11*N2 -> 233.33333 | E18: =D18*$K$2 -> 343000 | F18: COMBO | I18: 1.5 | J18: =D18*$K$2*I18 -> 514500 | K18: =J18*1.1 -> 565950 | L18: =J18*5/6 -> 428750
D19: =J19/1.5 -> 100 | E19: =D19*$K$2 -> 147000 | F19: AUTO CPAP G1 | I19: 1.5 | J19: 150 | K19: =J19*1.1 -> 165 | L19: =J19*5/6 -> 125
A20: 42682 | B20: 1501002 | C20: BMC | D20: 50 | E20: =D20*$K$2 -> 73500 | F20: TURBINA AUTOCPAP RESmartAUTO | I20: 1.5 | J20: =D20*$K$2*I20 -> 110250 | K20: =J20*1.1 -> 121275 | L20: =J20*5/6 -> 91875
A21: 42682 | B21: 1502009 | C21: BMC | D21: 80 | E21: =D21*$K$2 -> 117600 | F21: PLACA PRINCIPAL AUTO CPAP RESmart AUTO | I21: 1.5 | J21: =D21*$K$2*I21 -> 176400 | K21: =J21*1.1 -> 194040 | L21: =J21*5/6 -> 147000
E22: =D22*$K$2 -> 0 | F22: GII | I22: 1.5 | K22: =J22*1.1 -> 0 | L22: =J22*5/6 -> 0
B23: 1103001 | D23: =J23/1.5 -> 166.66667 | E23: =D23*$K$2 -> 245000 | F23: E-20C-H-O | I23: 1.5 | J23: 250 | K23: =J23*1.1 -> 275 | L23: =J23*5/6 -> 208.33333
A24: 44992 | B24: TR001 | C24: BMC | D24: =D23*N3 -> 100 | E24: =D24*$K$2 -> 147000 | F24: TURBINA nP2-C2 | I24: 1.5 | J24: =D24*$K$2*I24 -> 220500 | K24: =J24*1.1 -> 242550 | L24: =J24*5/6 -> 183750
A25: 44992 | B25: 1502006 | C25: BMC | D25: =D23*N4 -> 83.333333 | E25: =D25*$K$2 -> 122500 | F25: PLACA DE CONTROL E-20C-H-O | I25: 1.5 | J25: =D25*$K$2*I25 -> 183750 | K25: =J25*1.1 -> 202125 | L25: =J25*5/6 -> 153125
D26: =D23*$N$2 -> 116.66667 | E26: =D26*$K$2 -> 171500 | F26: COMBO | I26: 1.5 | J26: =D26*$K$2*I26 -> 257250 | K26: =J26*1.1 -> 282975 | L26: =J26*5/6 -> 214375
B27: 1105001 | D27: =J27/1.5 -> 200 | E27: =D27*$K$2 -> 294000 | F27: E-20A-H-O | I27: 1.5 | J27: 300 | K27: =J27*1.1 -> 330 | L27: =J27*5/6 -> 250
A28: 44992 | B28: TR002 | C28: BMC | D28: =D27*N3 -> 120 | E28: =D28*$K$2 -> 176400 | F28: TURBINA nP2-M3+ | I28: 1.5 | J28: =D28*$K$2*I28 -> 264600 | K28: =J28*1.1 -> 291060 | L28: =J28*5/6 -> 220500
A29: 44992 | B29: 1502001 | C29: BMC | D29: =D27*N4 -> 100 | E29: =D29*$K$2 -> 147000 | F29: PLACA DE CONTROL E-20A-H-O | I29: 1.5 | J29: =D29*$K$2*I29 -> 220500 | K29: =J29*1.1 -> 242550 | L29: =J29*5/6 -> 183750
A30: 44992 | C30: BMC | D30: =D27*N2 -> 140 | E30: =D30*$K$2 -> 205800 | F30: COMBO | I30: 1.5 | J30: =D30*$K$2*I30 -> 308700 | K30: =J30*1.1 -> 339570 | L30: =J30*5/6 -> 257250
B31: 1104002 | D31: =J31/1.5 -> 566.66667 | E31: =D31*$K$2 -> 833000 | F31: BPAP T-25T | I31: 1.5 | J31: 850 | K31: =J31*1.1 -> 935 | L31: =J31*5/6 -> 708.33333
A32: 44992 | B32: 1501005 | C32: BMC | D32: =D31*N3 -> 340 | E32: =D32*$K$2 -> 499800 | F32: TURBINA G2 T | I32: 1.5 | J32: =D32*$K$2*I32 -> 749700 | K32: =J32*1.1 -> 824670 | L32: =J32*5/6 -> 624750
A33: 44992 | B33: PR001 | C33: BMC | D33: =D31*N4 -> 283.33333 | E33: =D33*$K$2 -> 416500 | F33: PLACA DE CONTROL T-25T | I33: 1.5 | J33: =D33*$K$2*I33 -> 624750 | K33: =J33*1.1 -> 687225 | L33: =J33*5/6 -> 520625
A34: 44992 | C34: BMC | D34: =D31*N2 -> 396.66667 | E34: =D34*$K$2 -> 583100 | F34: COMBO | I34: 1.5 | J34: =D34*$K$2*I34 -> 874650 | K34: =J34*1.1 -> 962115 | L34: =J34*5/6 -> 728875
B35: 1104003 | D35: =J35/1.5 -> 633.33333 | E35: =D35*$K$2 -> 931000 | F35: BPAP Y-25T | I35: 1.5 | J35: 950 | K35: =J35*1.1 -> 1045 | L35: =J35*5/6 -> 791.66667
B36: PF-001 | D36: =D35*N3 -> 380 | E36: =D36*$K$2 -> 558600 | F36: TURBINA G2 T | I36: 1.5 | J36: =D32*$K$2*I32 -> 749700 | K36: =J36*1.1 -> 824670 | L36: =J36*5/6 -> 624750
B37: PR002 | D37: =D35*N4 -> 316.66667 | E37: =D37*$K$2 -> 465500 | F37: PLACA CONTROL Y-25T | I37: 1.5 | J37: =D33*$K$2*I33 -> 624750 | K37: =J37*1.1 -> 687225 | L37: =J37*5/6 -> 520625
D38: =D35*N2 -> 443.33333 | E38: =D38*$K$2 -> 651700 | F38: COMBO | I38: 1.5 | J38: =D34*$K$2*I34 -> 874650 | K38: =J38*1.1 -> 962115 | L38: =J38*5/6 -> 728875
A39: 44992 | B39: SP557 | C39: BMC | E39: =D39*$K$2 -> 0 | F39: PLACA DE CONTROL Y-30T | I39: 1.5 | K39: =J39*1.1 -> 0 | L39: =J39*5/6 -> 0
A40: 44992 | B40: SP722 | C40: BMC | E40: =D40*$K$2 -> 0 | F40: PLACA DE CONTROL Y-30A | I40: 1.5 | J40: =D40*$K$2*I40 -> 0 | K40: =J40*1.1 -> 0 | L40: =J40*5/6 -> 0
E41: =D41*$K$2 -> 0 | F41: G2S | I41: 1.5 | K41: =J41*1.1 -> 0 | L41: =J41*5/6 -> 0
...

Sheet CÓDIGOS
A1: codigo | B1: descripcion | C1: origen | D1: descripcion_maestro | E1: descripcion_begerman | F1: cod_prov | G1: proveedor | H1: equipo | I1: conflicto_desc
A2: 1199015 | B2: Regulador de oxígeno ZS 0-15 sin humidificador | C2: begerman | E2: Regulador de oxígeno ZS 0-15 sin humidificador | I2: False
A3: 1199016 | B3: Carro p/cilindro de oxígeno ZS | C3: begerman | E3: Carro p/cilindro de oxígeno ZS | I3: False
A4: 1199017 | B4: Cabezal de temperatura oral y p/axilas FT10 | C4: begerman | E4: Cabezal de temperatura oral y p/axilas FT10 | I4: False
A5: 1199018 | B5: Cable paciente ECG 10 deriv. compatible EDAN | C5: begerman | E5: Cable paciente ECG 10 deriv. compatible EDAN | I5: False
A6: 1199019 | B6: Cable paciente ECG 5 deriv. compatible MEDITECH | C6: begerman | E6: Cable paciente ECG 5 deriv. compatible MEDITECH | I6: False
A7: 1199020 | B7: Cobertor p/sensor temp. WELCHALLYN p/EDAN x25 u | C7: begerman | E7: Cobertor p/sensor temp. WELCHALLYN p/EDAN x25 u | I7: False
A8: 1199021 | B8: Prolongador de oximetría COVIDIEN DOC10 | C8: begerman | E8: Prolongador de oximetría COVIDIEN DOC10 | I8: False
A9: 1199022 | B9: Articulo para reutilzar | C9: begerman | E9: Articulo para reutilzar | I9: False
A10: 1199023 | B10: Sensor de sat. c/broche adulto MINDRAY 3m p/EDAN | C10: begerman | E10: Sensor de sat. c/broche adulto MINDRAY 3m p/EDAN | I10: False
A11: 1199024 | B11: Sensor de sat. c/broche adulto p/NONIN 1,2m 325BCD | C11: begerman | E11: Sensor de sat. c/broche adulto p/NONIN 1,2m 325BCD | I11: False
A12: 1199025 | B12: Sensor de sat. c/broche NELLCOR neonatal 315N | C12: begerman | E12: Sensor de sat. c/broche NELLCOR neonatal 315N | I12: False
A13: 1199026 | B13: Articulo para reutilizar | C13: begerman | E13: Articulo para reutilizar | I13: False
... A407: 1601002 | B407: Instalación y config. de central de monitoreo | C407: begerman | E407: Instalación y config. de central de monitoreo | I407: False
A408: AE001 | B408: Caja de embalaje C-500 | C408: ambos | D408: CAJA DE EMBALAJE C-500 | E408: Caja de embalaje C-500 | G408: TURANO | H408: C-500 | I408: False
A409: AE002 | B409: Caja de embalaje A-550 | C409: ambos | D409: CAJA DE EMBALAJE A-550 | E409: Caja de embalaje A-550 | G409: TURANO | H409: A-550 | I409: False
A410: AE003 | B410: Bolso de traslado p/aspirador | C410: ambos | D410: BOLSO DE TRASLADO | E410: Bolso de traslado p/aspirador | G410: MATYCUER | H410: A-550 | I410: True
A411: AR001 | B411: Arandela plana ala angosta 4 MM | C411: ambos | D411: ARANDELA PLANA ALA ANGOSTA 4MM | E411: Arandela plana ala angosta 4 MM | G411: MOYANO | H411: A-600 | I411: False
A412: AR002 | B412: Arandela estrella 4 MM | C412: ambos | D412: ARANDELA ESTRELLA 4 MM | E412: Arandela estrella 4 MM | G412: MOYANO | H412: A-550 | I412: False
A413: AR003 | B413: Arandela plana 3 MM | C413: ambos | D413: ARANDELA PLANA 3MM | E413: Arandela plana 3 MM | G413: MOYANO | H413: C-500/A-600 | I413: False
A414: AR004 | B414: Arandela chapista M5 x 21 MM | C414: ambos | D414: ARANDELA CHAPISTA M5 X 21 MM | E414: Arandela chapista M5 x 21 MM | G414: MOYANO | H414: A-600 | I414: False
A415: AR005 | B415: Arandela chapista 3/8 x 40 MM | C415: ambos | D415: ARANDELA CHAPISTA 3/8 X 40 MM | E415: Arandela chapista 3/8 x 40 MM | G415: MOYANO | H415: A-600 | I415: False
A416: AR006 | B416: Arandela chapista M4 | C416: ambos | D416: ARANDELA CHAPISTA M4 | E416: Arandela chapista M4 | I416: False
A417: AR007 | B417: Arandela estrella 3 MM | C417: ambos | D417: ARANDELA ESTRELLA 3 MM | E417: Arandela estrella 3 MM | I417: False
A418: AR008 | B418: Arandela plana 5 MM | C418: ambos | D418: ARANDELA PLANA 5MM | E418: Arandela plana 5 MM | I418: False
A419: AR009 | B419: Arandela estrella 5 MM | C419: ambos | D419: ARANDELA ESTRELLA 5 MM | E419: Arandela estrella 5 MM | I419: False
A420: AR-010 | B420: ARANDELA DE FIBRA 3 MM ALA ANCHA | C420: maestro | D420: ARANDELA DE FIBRA 3 MM ALA ANCHA | I420: False
A421: AR-011 | B421: ARANDELA DE FIBRA 6 MM ALA ANCHA | C421: maestro | D421: ARANDELA DE FIBRA 6 MM ALA ANCHA | I421: False
A422: AR-012 | B422: ARANDELA PLANA 3/32" | C422: maestro | D422: ARANDELA PLANA 3/32" | H422: A-550 | I422: False
A423: AR-013 | B423: ARANDELA PLANA 3 x 10mm | C423: maestro | D423: ARANDELA PLANA 3 x 10mm | I423: False
A424: BA303 | B424: Base cargador de batería G3 c/fuente ext. | C424: ambos | D424: BASE CARGADOR DE BATERIA G3 C/FUENTE EXT. | E424: Base cargador de batería G3 c/fuente ext. | G424: INOGEN | H424: G3 HF | I424: True
A425: BA306 | B425: Fuente de alimentación externa G3, G4, G5 | C425: ambos | D425: FUENTE DE ALIMENTACION EXTERNA G3.G4,G5 | E425: Fuente de alimentación externa G3, G4, G5 | G425: INOGEN | H425: G3-G4-G5 | I425: True
A426: BA401 | B426: Inogen G4 AC Power Supply | C426: begerman | E426: Inogen G4 AC Power Supply | I426: False
A427: BI001 | B427: Bisagra portillo Incubadora Medix PC307 | C427: ambos | D427: BISAGRA INCUBADORA MEDIX PC-307 | E427: Bisagra portillo Incubadora Medix PC307 | G427: MEDIX | H427: INCUBADORA | I427: True
A428: BT001 | B428: Bateria Litio Concentrador Portatil JAY-10D | C428: ambos | D428: BATERIA LITIO CONCENTRADOR PORTATIL | E428: Bateria Litio Concentrador Portatil JAY-10D | G428: LONGFIAN | H428: JAY10-D | I428: True
A429: CA001 | B429: Cable 1 x 0,5 M2 Rojo | C429: ambos | D429: CABLE 1 X 1.5 M2 ROJO | E429: Cable 1 x 0,5 M2 Rojo | I429: True
A430: CA002 | B430: Cable 1 x 0,5 M2 Negro | C430: ambos | D430: CABLE 1 X 1.5 M2 NEGRO | E430: Cable 1 x 0,5 M2 Negro | I430: True
A431: CE001 | B431: Termistor K 164 10K | C431: ambos | D431: TERMISTOR K 164 10K | E431: Termistor K 164 10K | F431: TE2556130 | G431: ELEMON | H431: C-500 | I431: False
A432: CE-002 | B432: CIRC.INTEGRADO LM 358 | C432: maestro | D432: CIRC.INTEGRADO LM 358 | F432: LM358N | G432: DIMEXAR | H432: C-500 | I432: False
A433: CE-003 | B433: TRANSISTOR MOSFET 6N60 (IRF830) | C433: maestro | D433: TRANSISTOR MOSFET 6N60 (IRF830) | G433: DIMEXAR | H433: C-500 | I433: False
...

Sheet MEDIX
H1: DÓLAR | I1: 268.21
A2: FECHA | B2: PROVEEDOR | C2: COSTO NETO | D2: REPUESTO | E2: PRECIO
A3: 45107 | B3: INTRA | C3: 22.5 | D3: BISAGRA | E3: =((C3*1.35)*I$1) -> 8146.8788
A4: 45107 | B4: INTRA | C4: 938 | D4: MOTOR | E4: =((C4*1.35)*I$1) -> 339634.32
A5: 45107 | B5: INTRA | C5: 21 | D5: PASACANULA LATERAL MAX | E5: =((C5*1.35)*I$1) -> 7603.7535
A6: 45107 | B6: INTRA | C6: 6 | D6: BURLETE PORTILLO PUERTA LATERAL | E6: =((C6*1.35)*I$1) -> 2172.501
A7: 45107 | B7: INTRA | C7: 126 | D7: DOBLE TECHO | E7: =((C7*1.35)*I$1) -> 45622.521
A8: 45107 | B8: INTRA | C8: 11.5 | D8: PASA CANULA CRISTAL | E8: =((C8*1.35)*I$1) -> 4163.9603
A9: 45107 | B9: INTRA | C9: 73 | D9: PORTILLO IRIS | E9: =((C9*1.35)*I$1) -> 26432.095
A10: 45107 | B10: INTRA | C10: 25.5 | D10: MANGA PORTILLO IRIS | E10: =((C10*1.35)*I$1) -> 9233.1292
A11: 45107 | B11: INTRA | C11: 8.5 | D11: ARO SUJECION IRIS | E11: =((C11*1.35)*I$1) -> 3077.7097
A12: 45107 | B12: INTRA | C12: 7 | D12: BURLETE CIERRE PCI | E12: =((C12*1.35)*I$1) -> 2534.5845
C13: 75 | D13: FILTRO X1 305 | E13: =((C13*1.35)*I$1) -> 27156.262
